[2024-05-13T17:34:00.054+0000] {taskinstance.py:1979} INFO - Dependencies all met for dep_context=non-requeueable deps ti=<TaskInstance: live_ademe.process_results manual__2024-05-13T17:33:53.292669+00:00 [queued]>
[2024-05-13T17:34:00.066+0000] {taskinstance.py:1979} INFO - Dependencies all met for dep_context=requeueable deps ti=<TaskInstance: live_ademe.process_results manual__2024-05-13T17:33:53.292669+00:00 [queued]>
[2024-05-13T17:34:00.066+0000] {taskinstance.py:2193} INFO - Starting attempt 1 of 2
[2024-05-13T17:34:00.090+0000] {taskinstance.py:2217} INFO - Executing <Task(PythonOperator): process_results> on 2024-05-13 17:33:53.292669+00:00
[2024-05-13T17:34:00.099+0000] {standard_task_runner.py:60} INFO - Started process 24629 to run task
[2024-05-13T17:34:00.107+0000] {standard_task_runner.py:87} INFO - Running: ['***', 'tasks', 'run', 'live_ademe', 'process_results', 'manual__2024-05-13T17:33:53.292669+00:00', '--job-id', '104', '--raw', '--subdir', 'DAGS_FOLDER/load.py', '--cfg-path', '/tmp/tmpqhclw2fj']
[2024-05-13T17:34:00.111+0000] {standard_task_runner.py:88} INFO - Job 104: Subtask process_results
[2024-05-13T17:34:00.179+0000] {task_command.py:423} INFO - Running <TaskInstance: live_ademe.process_results manual__2024-05-13T17:33:53.292669+00:00 [running]> on host 86724742ac03
[2024-05-13T17:34:00.297+0000] {taskinstance.py:2513} INFO - Exporting env vars: AIRFLOW_CTX_DAG_EMAIL='***@example.com' AIRFLOW_CTX_DAG_OWNER='***' AIRFLOW_CTX_DAG_ID='live_ademe' AIRFLOW_CTX_TASK_ID='process_results' AIRFLOW_CTX_EXECUTION_DATE='2024-05-13T17:33:53.292669+00:00' AIRFLOW_CTX_TRY_NUMBER='1' AIRFLOW_CTX_DAG_RUN_ID='manual__2024-05-13T17:33:53.292669+00:00'
[2024-05-13T17:34:00.317+0000] {taskinstance.py:2731} ERROR - Task failed with exception
Traceback (most recent call last):
  File "/home/airflow/.local/lib/python3.8/site-packages/airflow/models/taskinstance.py", line 444, in _execute_task
    result = _execute_callable(context=context, **execute_callable_kwargs)
  File "/home/airflow/.local/lib/python3.8/site-packages/airflow/models/taskinstance.py", line 414, in _execute_callable
    return execute_callable(context=context, **execute_callable_kwargs)
  File "/home/airflow/.local/lib/python3.8/site-packages/airflow/operators/python.py", line 200, in execute
    return_value = self.execute_callable()
  File "/home/airflow/.local/lib/python3.8/site-packages/airflow/operators/python.py", line 217, in execute_callable
    return self.python_callable(*self.op_args, **self.op_kwargs)
  File "/opt/airflow/dags/load.py", line 106, in process_results
    with open(data_filename, "w", encoding="utf-8") as file:
FileNotFoundError: [Errno 2] No such file or directory: '/opt/airflow/data/ademe-dpe-tertiaire/data_1715621640.json'
[2024-05-13T17:34:00.329+0000] {taskinstance.py:1149} INFO - Marking task as UP_FOR_RETRY. dag_id=live_ademe, task_id=process_results, execution_date=20240513T173353, start_date=20240513T173400, end_date=20240513T173400
[2024-05-13T17:34:00.345+0000] {standard_task_runner.py:107} ERROR - Failed to execute job 104 for task process_results ([Errno 2] No such file or directory: '/opt/airflow/data/ademe-dpe-tertiaire/data_1715621640.json'; 24629)
[2024-05-13T17:34:00.365+0000] {local_task_job_runner.py:234} INFO - Task exited with return code 1
[2024-05-13T17:34:00.408+0000] {taskinstance.py:3312} INFO - 0 downstream tasks scheduled from follow-on schedule check
