[2024-05-12T12:05:55.674+0000] {taskinstance.py:1979} INFO - Dependencies all met for dep_context=non-requeueable deps ti=<TaskInstance: ademe_data.ademe_api manual__2024-05-12T12:05:53.937090+00:00 [queued]>
[2024-05-12T12:05:55.695+0000] {taskinstance.py:1979} INFO - Dependencies all met for dep_context=requeueable deps ti=<TaskInstance: ademe_data.ademe_api manual__2024-05-12T12:05:53.937090+00:00 [queued]>
[2024-05-12T12:05:55.696+0000] {taskinstance.py:2193} INFO - Starting attempt 1 of 2
[2024-05-12T12:05:55.717+0000] {taskinstance.py:2217} INFO - Executing <Task(PythonOperator): ademe_api> on 2024-05-12 12:05:53.937090+00:00
[2024-05-12T12:05:55.727+0000] {standard_task_runner.py:60} INFO - Started process 52754 to run task
[2024-05-12T12:05:55.734+0000] {standard_task_runner.py:87} INFO - Running: ['***', 'tasks', 'run', 'ademe_data', 'ademe_api', 'manual__2024-05-12T12:05:53.937090+00:00', '--job-id', '21', '--raw', '--subdir', 'DAGS_FOLDER/load_data.py', '--cfg-path', '/tmp/tmpyg0qc7fp']
[2024-05-12T12:05:55.738+0000] {standard_task_runner.py:88} INFO - Job 21: Subtask ademe_api
[2024-05-12T12:05:55.807+0000] {task_command.py:423} INFO - Running <TaskInstance: ademe_data.ademe_api manual__2024-05-12T12:05:53.937090+00:00 [running]> on host 86724742ac03
[2024-05-12T12:05:55.902+0000] {taskinstance.py:2513} INFO - Exporting env vars: AIRFLOW_CTX_DAG_EMAIL='yassinemed.essamadi@gmail.com' AIRFLOW_CTX_DAG_OWNER='***' AIRFLOW_CTX_DAG_ID='ademe_data' AIRFLOW_CTX_TASK_ID='ademe_api' AIRFLOW_CTX_EXECUTION_DATE='2024-05-12T12:05:53.937090+00:00' AIRFLOW_CTX_TRY_NUMBER='1' AIRFLOW_CTX_DAG_RUN_ID='manual__2024-05-12T12:05:53.937090+00:00'
[2024-05-12T12:05:55.905+0000] {taskinstance.py:2731} ERROR - Task failed with exception
Traceback (most recent call last):
  File "/home/airflow/.local/lib/python3.8/site-packages/airflow/models/taskinstance.py", line 444, in _execute_task
    result = _execute_callable(context=context, **execute_callable_kwargs)
  File "/home/airflow/.local/lib/python3.8/site-packages/airflow/models/taskinstance.py", line 414, in _execute_callable
    return execute_callable(context=context, **execute_callable_kwargs)
  File "/home/airflow/.local/lib/python3.8/site-packages/airflow/operators/python.py", line 200, in execute
    return_value = self.execute_callable()
  File "/home/airflow/.local/lib/python3.8/site-packages/airflow/operators/python.py", line 217, in execute_callable
    return self.python_callable(*self.op_args, **self.op_kwargs)
  File "/opt/airflow/dags/load_data.py", line 79, in ademe_api
    assert os.path.isfile(URL_FILE)
AssertionError
[2024-05-12T12:05:55.915+0000] {taskinstance.py:1149} INFO - Marking task as UP_FOR_RETRY. dag_id=ademe_data, task_id=ademe_api, execution_date=20240512T120553, start_date=20240512T120555, end_date=20240512T120555
[2024-05-12T12:05:55.934+0000] {standard_task_runner.py:107} ERROR - Failed to execute job 21 for task ademe_api (; 52754)
[2024-05-12T12:05:55.946+0000] {local_task_job_runner.py:234} INFO - Task exited with return code 1
[2024-05-12T12:05:55.969+0000] {taskinstance.py:3312} INFO - 0 downstream tasks scheduled from follow-on schedule check
