[2024-05-14T11:46:24.004+0000] {taskinstance.py:1979} INFO - Dependencies all met for dep_context=non-requeueable deps ti=<TaskInstance: ademe_models.promote_model_task manual__2024-05-14T11:45:51.847382+00:00 [queued]>
[2024-05-14T11:46:24.456+0000] {taskinstance.py:1979} INFO - Dependencies all met for dep_context=requeueable deps ti=<TaskInstance: ademe_models.promote_model_task manual__2024-05-14T11:45:51.847382+00:00 [queued]>
[2024-05-14T11:46:24.456+0000] {taskinstance.py:2193} INFO - Starting attempt 1 of 1
[2024-05-14T11:46:24.487+0000] {taskinstance.py:2217} INFO - Executing <Task(PythonOperator): promote_model_task> on 2024-05-14 11:45:51.847382+00:00
[2024-05-14T11:46:24.515+0000] {standard_task_runner.py:60} INFO - Started process 40473 to run task
[2024-05-14T11:46:24.530+0000] {standard_task_runner.py:87} INFO - Running: ['***', 'tasks', 'run', 'ademe_models', 'promote_model_task', 'manual__2024-05-14T11:45:51.847382+00:00', '--job-id', '213', '--raw', '--subdir', 'DAGS_FOLDER/predict.py', '--cfg-path', '/tmp/tmphwfyox8v']
[2024-05-14T11:46:24.533+0000] {standard_task_runner.py:88} INFO - Job 213: Subtask promote_model_task
[2024-05-14T11:46:24.754+0000] {task_command.py:423} INFO - Running <TaskInstance: ademe_models.promote_model_task manual__2024-05-14T11:45:51.847382+00:00 [running]> on host 86724742ac03
[2024-05-14T11:46:24.926+0000] {taskinstance.py:2513} INFO - Exporting env vars: AIRFLOW_CTX_DAG_OWNER='***' AIRFLOW_CTX_DAG_ID='ademe_models' AIRFLOW_CTX_TASK_ID='promote_model_task' AIRFLOW_CTX_EXECUTION_DATE='2024-05-14T11:45:51.847382+00:00' AIRFLOW_CTX_TRY_NUMBER='1' AIRFLOW_CTX_DAG_RUN_ID='manual__2024-05-14T11:45:51.847382+00:00'
[2024-05-14T11:46:25.050+0000] {taskinstance.py:2731} ERROR - Task failed with exception
Traceback (most recent call last):
  File "/home/airflow/.local/lib/python3.8/site-packages/airflow/models/taskinstance.py", line 444, in _execute_task
    result = _execute_callable(context=context, **execute_callable_kwargs)
  File "/home/airflow/.local/lib/python3.8/site-packages/airflow/models/taskinstance.py", line 414, in _execute_callable
    return execute_callable(context=context, **execute_callable_kwargs)
  File "/home/airflow/.local/lib/python3.8/site-packages/airflow/operators/python.py", line 200, in execute
    return_value = self.execute_callable()
  File "/home/airflow/.local/lib/python3.8/site-packages/airflow/operators/python.py", line 217, in execute_callable
    return self.python_callable(*self.op_args, **self.op_kwargs)
  File "/opt/airflow/dags/predict.py", line 243, in promote_model
    X, y = load_data_for_inference(200)
  File "/opt/airflow/dags/predict.py", line 155, in load_data_for_inference
    data = data.astype(int)
  File "/home/airflow/.local/lib/python3.8/site-packages/pandas/core/generic.py", line 6324, in astype
    new_data = self._mgr.astype(dtype=dtype, copy=copy, errors=errors)
  File "/home/airflow/.local/lib/python3.8/site-packages/pandas/core/internals/managers.py", line 451, in astype
    return self.apply(
  File "/home/airflow/.local/lib/python3.8/site-packages/pandas/core/internals/managers.py", line 352, in apply
    applied = getattr(b, f)(**kwargs)
  File "/home/airflow/.local/lib/python3.8/site-packages/pandas/core/internals/blocks.py", line 511, in astype
    new_values = astype_array_safe(values, dtype, copy=copy, errors=errors)
  File "/home/airflow/.local/lib/python3.8/site-packages/pandas/core/dtypes/astype.py", line 242, in astype_array_safe
    new_values = astype_array(values, dtype, copy=copy)
  File "/home/airflow/.local/lib/python3.8/site-packages/pandas/core/dtypes/astype.py", line 187, in astype_array
    values = _astype_nansafe(values, dtype, copy=copy)
  File "/home/airflow/.local/lib/python3.8/site-packages/pandas/core/dtypes/astype.py", line 138, in _astype_nansafe
    return arr.astype(dtype, copy=True)
ValueError: invalid literal for int() with base 10: 'A'
[2024-05-14T11:46:25.074+0000] {taskinstance.py:1149} INFO - Marking task as FAILED. dag_id=ademe_models, task_id=promote_model_task, execution_date=20240514T114551, start_date=20240514T114624, end_date=20240514T114625
[2024-05-14T11:46:25.104+0000] {standard_task_runner.py:107} ERROR - Failed to execute job 213 for task promote_model_task (invalid literal for int() with base 10: 'A'; 40473)
[2024-05-14T11:46:25.149+0000] {local_task_job_runner.py:234} INFO - Task exited with return code 1
[2024-05-14T11:46:25.185+0000] {taskinstance.py:3312} INFO - 0 downstream tasks scheduled from follow-on schedule check
