[2024-05-13T16:19:16.233+0000] {taskinstance.py:1979} INFO - Dependencies all met for dep_context=non-requeueable deps ti=<TaskInstance: live_ademe.save_postgresdb manual__2024-05-13T16:14:08.231080+00:00 [queued]>
[2024-05-13T16:19:16.250+0000] {taskinstance.py:1979} INFO - Dependencies all met for dep_context=requeueable deps ti=<TaskInstance: live_ademe.save_postgresdb manual__2024-05-13T16:14:08.231080+00:00 [queued]>
[2024-05-13T16:19:16.251+0000] {taskinstance.py:2193} INFO - Starting attempt 2 of 2
[2024-05-13T16:19:16.287+0000] {taskinstance.py:2217} INFO - Executing <Task(PythonOperator): save_postgresdb> on 2024-05-13 16:14:08.231080+00:00
[2024-05-13T16:19:16.302+0000] {standard_task_runner.py:60} INFO - Started process 23517 to run task
[2024-05-13T16:19:16.310+0000] {standard_task_runner.py:87} INFO - Running: ['***', 'tasks', 'run', 'live_ademe', 'save_postgresdb', 'manual__2024-05-13T16:14:08.231080+00:00', '--job-id', '87', '--raw', '--subdir', 'DAGS_FOLDER/load.py', '--cfg-path', '/tmp/tmp8i6tc8mu']
[2024-05-13T16:19:16.312+0000] {standard_task_runner.py:88} INFO - Job 87: Subtask save_postgresdb
[2024-05-13T16:19:16.415+0000] {task_command.py:423} INFO - Running <TaskInstance: live_ademe.save_postgresdb manual__2024-05-13T16:14:08.231080+00:00 [running]> on host 86724742ac03
[2024-05-13T16:19:16.577+0000] {taskinstance.py:2513} INFO - Exporting env vars: AIRFLOW_CTX_DAG_EMAIL='***@example.com' AIRFLOW_CTX_DAG_OWNER='***' AIRFLOW_CTX_DAG_ID='live_ademe' AIRFLOW_CTX_TASK_ID='save_postgresdb' AIRFLOW_CTX_EXECUTION_DATE='2024-05-13T16:14:08.231080+00:00' AIRFLOW_CTX_TRY_NUMBER='2' AIRFLOW_CTX_DAG_RUN_ID='manual__2024-05-13T16:14:08.231080+00:00'
[2024-05-13T16:19:16.600+0000] {taskinstance.py:2731} ERROR - Task failed with exception
Traceback (most recent call last):
  File "/home/airflow/.local/lib/python3.8/site-packages/airflow/models/taskinstance.py", line 444, in _execute_task
    result = _execute_callable(context=context, **execute_callable_kwargs)
  File "/home/airflow/.local/lib/python3.8/site-packages/airflow/models/taskinstance.py", line 414, in _execute_callable
    return execute_callable(context=context, **execute_callable_kwargs)
  File "/home/airflow/.local/lib/python3.8/site-packages/airflow/operators/python.py", line 200, in execute
    return_value = self.execute_callable()
  File "/home/airflow/.local/lib/python3.8/site-packages/airflow/operators/python.py", line 217, in execute_callable
    return self.python_callable(*self.op_args, **self.op_kwargs)
  File "/opt/airflow/dags/load.py", line 103, in save_postgresdb
    data = pd.DataFrame(data["results"])
NameError: name 'pd' is not defined
[2024-05-13T16:19:16.616+0000] {taskinstance.py:1149} INFO - Marking task as FAILED. dag_id=live_ademe, task_id=save_postgresdb, execution_date=20240513T161408, start_date=20240513T161916, end_date=20240513T161916
[2024-05-13T16:19:16.640+0000] {standard_task_runner.py:107} ERROR - Failed to execute job 87 for task save_postgresdb (name 'pd' is not defined; 23517)
[2024-05-13T16:19:16.664+0000] {local_task_job_runner.py:234} INFO - Task exited with return code 1
[2024-05-13T16:19:16.695+0000] {taskinstance.py:3312} INFO - 0 downstream tasks scheduled from follow-on schedule check
