[2024-05-14T11:20:16.709+0000] {taskinstance.py:1979} INFO - Dependencies all met for dep_context=non-requeueable deps ti=<TaskInstance: ademe_models.train_model_task manual__2024-05-14T11:20:10.346165+00:00 [queued]>
[2024-05-14T11:20:17.156+0000] {taskinstance.py:1979} INFO - Dependencies all met for dep_context=requeueable deps ti=<TaskInstance: ademe_models.train_model_task manual__2024-05-14T11:20:10.346165+00:00 [queued]>
[2024-05-14T11:20:17.157+0000] {taskinstance.py:2193} INFO - Starting attempt 1 of 1
[2024-05-14T11:20:17.189+0000] {taskinstance.py:2217} INFO - Executing <Task(PythonOperator): train_model_task> on 2024-05-14 11:20:10.346165+00:00
[2024-05-14T11:20:17.209+0000] {standard_task_runner.py:60} INFO - Started process 40070 to run task
[2024-05-14T11:20:17.223+0000] {standard_task_runner.py:87} INFO - Running: ['***', 'tasks', 'run', 'ademe_models', 'train_model_task', 'manual__2024-05-14T11:20:10.346165+00:00', '--job-id', '207', '--raw', '--subdir', 'DAGS_FOLDER/predict.py', '--cfg-path', '/tmp/tmpuat5ka8r']
[2024-05-14T11:20:17.226+0000] {standard_task_runner.py:88} INFO - Job 207: Subtask train_model_task
[2024-05-14T11:20:17.333+0000] {task_command.py:423} INFO - Running <TaskInstance: ademe_models.train_model_task manual__2024-05-14T11:20:10.346165+00:00 [running]> on host 86724742ac03
[2024-05-14T11:20:17.504+0000] {taskinstance.py:2513} INFO - Exporting env vars: AIRFLOW_CTX_DAG_OWNER='***' AIRFLOW_CTX_DAG_ID='ademe_models' AIRFLOW_CTX_TASK_ID='train_model_task' AIRFLOW_CTX_EXECUTION_DATE='2024-05-14T11:20:10.346165+00:00' AIRFLOW_CTX_TRY_NUMBER='1' AIRFLOW_CTX_DAG_RUN_ID='manual__2024-05-14T11:20:10.346165+00:00'
[2024-05-14T11:20:17.669+0000] {taskinstance.py:2731} ERROR - Task failed with exception
Traceback (most recent call last):
  File "/home/airflow/.local/lib/python3.8/site-packages/airflow/models/taskinstance.py", line 444, in _execute_task
    result = _execute_callable(context=context, **execute_callable_kwargs)
  File "/home/airflow/.local/lib/python3.8/site-packages/airflow/models/taskinstance.py", line 414, in _execute_callable
    return execute_callable(context=context, **execute_callable_kwargs)
  File "/home/airflow/.local/lib/python3.8/site-packages/airflow/operators/python.py", line 200, in execute
    return_value = self.execute_callable()
  File "/home/airflow/.local/lib/python3.8/site-packages/airflow/operators/python.py", line 217, in execute_callable
    return self.python_callable(*self.op_args, **self.op_kwargs)
  File "/opt/airflow/dags/predict.py", line 190, in train_model
    data = load_data_for_training(n_samples=200)
  File "/opt/airflow/dags/predict.py", line 175, in load_data_for_training
    data = data.astype(int)
  File "/home/airflow/.local/lib/python3.8/site-packages/pandas/core/generic.py", line 6324, in astype
    new_data = self._mgr.astype(dtype=dtype, copy=copy, errors=errors)
  File "/home/airflow/.local/lib/python3.8/site-packages/pandas/core/internals/managers.py", line 451, in astype
    return self.apply(
  File "/home/airflow/.local/lib/python3.8/site-packages/pandas/core/internals/managers.py", line 352, in apply
    applied = getattr(b, f)(**kwargs)
  File "/home/airflow/.local/lib/python3.8/site-packages/pandas/core/internals/blocks.py", line 511, in astype
    new_values = astype_array_safe(values, dtype, copy=copy, errors=errors)
  File "/home/airflow/.local/lib/python3.8/site-packages/pandas/core/dtypes/astype.py", line 242, in astype_array_safe
    new_values = astype_array(values, dtype, copy=copy)
  File "/home/airflow/.local/lib/python3.8/site-packages/pandas/core/dtypes/astype.py", line 187, in astype_array
    values = _astype_nansafe(values, dtype, copy=copy)
  File "/home/airflow/.local/lib/python3.8/site-packages/pandas/core/dtypes/astype.py", line 138, in _astype_nansafe
    return arr.astype(dtype, copy=True)
ValueError: invalid literal for int() with base 10: 'A'
[2024-05-14T11:20:17.728+0000] {taskinstance.py:1149} INFO - Marking task as FAILED. dag_id=ademe_models, task_id=train_model_task, execution_date=20240514T112010, start_date=20240514T112016, end_date=20240514T112017
[2024-05-14T11:20:17.784+0000] {standard_task_runner.py:107} ERROR - Failed to execute job 207 for task train_model_task (invalid literal for int() with base 10: 'A'; 40070)
[2024-05-14T11:20:17.843+0000] {local_task_job_runner.py:234} INFO - Task exited with return code 1
[2024-05-14T11:20:17.900+0000] {taskinstance.py:3312} INFO - 0 downstream tasks scheduled from follow-on schedule check
