[2024-05-14T11:14:33.205+0000] {taskinstance.py:1979} INFO - Dependencies all met for dep_context=non-requeueable deps ti=<TaskInstance: ademe_models.train_model_task scheduled__2024-05-13T00:00:00+00:00 [queued]>
[2024-05-14T11:14:33.523+0000] {taskinstance.py:1979} INFO - Dependencies all met for dep_context=requeueable deps ti=<TaskInstance: ademe_models.train_model_task scheduled__2024-05-13T00:00:00+00:00 [queued]>
[2024-05-14T11:14:33.524+0000] {taskinstance.py:2193} INFO - Starting attempt 1 of 1
[2024-05-14T11:14:33.552+0000] {taskinstance.py:2217} INFO - Executing <Task(PythonOperator): train_model_task> on 2024-05-13 00:00:00+00:00
[2024-05-14T11:14:33.574+0000] {standard_task_runner.py:60} INFO - Started process 39970 to run task
[2024-05-14T11:14:33.592+0000] {standard_task_runner.py:87} INFO - Running: ['***', 'tasks', 'run', 'ademe_models', 'train_model_task', 'scheduled__2024-05-13T00:00:00+00:00', '--job-id', '202', '--raw', '--subdir', 'DAGS_FOLDER/predict.py', '--cfg-path', '/tmp/tmp1g7hqpbm']
[2024-05-14T11:14:33.595+0000] {standard_task_runner.py:88} INFO - Job 202: Subtask train_model_task
[2024-05-14T11:14:33.741+0000] {task_command.py:423} INFO - Running <TaskInstance: ademe_models.train_model_task scheduled__2024-05-13T00:00:00+00:00 [running]> on host 86724742ac03
[2024-05-14T11:14:33.976+0000] {taskinstance.py:2513} INFO - Exporting env vars: AIRFLOW_CTX_DAG_OWNER='***' AIRFLOW_CTX_DAG_ID='ademe_models' AIRFLOW_CTX_TASK_ID='train_model_task' AIRFLOW_CTX_EXECUTION_DATE='2024-05-13T00:00:00+00:00' AIRFLOW_CTX_TRY_NUMBER='1' AIRFLOW_CTX_DAG_RUN_ID='scheduled__2024-05-13T00:00:00+00:00'
[2024-05-14T11:14:34.171+0000] {taskinstance.py:2731} ERROR - Task failed with exception
Traceback (most recent call last):
  File "/home/airflow/.local/lib/python3.8/site-packages/airflow/models/taskinstance.py", line 444, in _execute_task
    result = _execute_callable(context=context, **execute_callable_kwargs)
  File "/home/airflow/.local/lib/python3.8/site-packages/airflow/models/taskinstance.py", line 414, in _execute_callable
    return execute_callable(context=context, **execute_callable_kwargs)
  File "/home/airflow/.local/lib/python3.8/site-packages/airflow/operators/python.py", line 200, in execute
    return_value = self.execute_callable()
  File "/home/airflow/.local/lib/python3.8/site-packages/airflow/operators/python.py", line 217, in execute_callable
    return self.python_callable(*self.op_args, **self.op_kwargs)
  File "/opt/airflow/dags/predict.py", line 192, in train_model
    data = load_data_for_training(n_samples=200)
  File "/opt/airflow/dags/predict.py", line 176, in load_data_for_training
    data.drop(columns="n_dpe", inplace=True)
  File "/home/airflow/.local/lib/python3.8/site-packages/pandas/core/frame.py", line 5258, in drop
    return super().drop(
  File "/home/airflow/.local/lib/python3.8/site-packages/pandas/core/generic.py", line 4549, in drop
    obj = obj._drop_axis(labels, axis, level=level, errors=errors)
  File "/home/airflow/.local/lib/python3.8/site-packages/pandas/core/generic.py", line 4591, in _drop_axis
    new_axis = axis.drop(labels, errors=errors)
  File "/home/airflow/.local/lib/python3.8/site-packages/pandas/core/indexes/base.py", line 6699, in drop
    raise KeyError(f"{list(labels[mask])} not found in axis")
KeyError: "['n_dpe'] not found in axis"
[2024-05-14T11:14:34.208+0000] {taskinstance.py:1149} INFO - Marking task as FAILED. dag_id=ademe_models, task_id=train_model_task, execution_date=20240513T000000, start_date=20240514T111433, end_date=20240514T111434
[2024-05-14T11:14:34.237+0000] {standard_task_runner.py:107} ERROR - Failed to execute job 202 for task train_model_task ("['n_dpe'] not found in axis"; 39970)
[2024-05-14T11:14:34.291+0000] {local_task_job_runner.py:234} INFO - Task exited with return code 1
[2024-05-14T11:14:34.347+0000] {taskinstance.py:3312} INFO - 0 downstream tasks scheduled from follow-on schedule check
