[2024-05-12T12:59:18.025+0000] {taskinstance.py:1979} INFO - Dependencies all met for dep_context=non-requeueable deps ti=<TaskInstance: live_ademe.interrogate_api manual__2024-05-12T12:54:12.422067+00:00 [queued]>
[2024-05-12T12:59:18.036+0000] {taskinstance.py:1979} INFO - Dependencies all met for dep_context=requeueable deps ti=<TaskInstance: live_ademe.interrogate_api manual__2024-05-12T12:54:12.422067+00:00 [queued]>
[2024-05-12T12:59:18.037+0000] {taskinstance.py:2193} INFO - Starting attempt 2 of 2
[2024-05-12T12:59:18.053+0000] {taskinstance.py:2217} INFO - Executing <Task(PythonOperator): interrogate_api> on 2024-05-12 12:54:12.422067+00:00
[2024-05-12T12:59:18.061+0000] {standard_task_runner.py:60} INFO - Started process 54 to run task
[2024-05-12T12:59:18.069+0000] {standard_task_runner.py:87} INFO - Running: ['***', 'tasks', 'run', 'live_ademe', 'interrogate_api', 'manual__2024-05-12T12:54:12.422067+00:00', '--job-id', '66', '--raw', '--subdir', 'DAGS_FOLDER/load.py', '--cfg-path', '/tmp/tmptqjotx60']
[2024-05-12T12:59:18.071+0000] {standard_task_runner.py:88} INFO - Job 66: Subtask interrogate_api
[2024-05-12T12:59:18.143+0000] {task_command.py:423} INFO - Running <TaskInstance: live_ademe.interrogate_api manual__2024-05-12T12:54:12.422067+00:00 [running]> on host 86724742ac03
[2024-05-12T12:59:18.236+0000] {taskinstance.py:2513} INFO - Exporting env vars: AIRFLOW_CTX_DAG_EMAIL='***@example.com' AIRFLOW_CTX_DAG_OWNER='***' AIRFLOW_CTX_DAG_ID='live_ademe' AIRFLOW_CTX_TASK_ID='interrogate_api' AIRFLOW_CTX_EXECUTION_DATE='2024-05-12T12:54:12.422067+00:00' AIRFLOW_CTX_TRY_NUMBER='2' AIRFLOW_CTX_DAG_RUN_ID='manual__2024-05-12T12:54:12.422067+00:00'
[2024-05-12T12:59:18.238+0000] {taskinstance.py:2731} ERROR - Task failed with exception
Traceback (most recent call last):
  File "/home/airflow/.local/lib/python3.8/site-packages/airflow/models/taskinstance.py", line 444, in _execute_task
    result = _execute_callable(context=context, **execute_callable_kwargs)
  File "/home/airflow/.local/lib/python3.8/site-packages/airflow/models/taskinstance.py", line 414, in _execute_callable
    return execute_callable(context=context, **execute_callable_kwargs)
  File "/home/airflow/.local/lib/python3.8/site-packages/airflow/operators/python.py", line 200, in execute
    return_value = self.execute_callable()
  File "/home/airflow/.local/lib/python3.8/site-packages/airflow/operators/python.py", line 217, in execute_callable
    return self.python_callable(*self.op_args, **self.op_kwargs)
  File "/opt/airflow/dags/load.py", line 45, in interrogate_api
    with open(URL_FILE, encoding="utf-8") as file:
PermissionError: [Errno 13] Permission denied: '/opt/airflow/data/api/url.json'
[2024-05-12T12:59:18.249+0000] {taskinstance.py:1149} INFO - Marking task as FAILED. dag_id=live_ademe, task_id=interrogate_api, execution_date=20240512T125412, start_date=20240512T125918, end_date=20240512T125918
[2024-05-12T12:59:18.265+0000] {standard_task_runner.py:107} ERROR - Failed to execute job 66 for task interrogate_api ([Errno 13] Permission denied: '/opt/airflow/data/api/url.json'; 54)
[2024-05-12T12:59:18.281+0000] {local_task_job_runner.py:234} INFO - Task exited with return code 1
[2024-05-12T12:59:18.307+0000] {taskinstance.py:3312} INFO - 0 downstream tasks scheduled from follow-on schedule check
