[2024-05-12T12:41:12.739+0000] {taskinstance.py:1979} INFO - Dependencies all met for dep_context=non-requeueable deps ti=<TaskInstance: live_ademe.interrogate_api manual__2024-05-12T12:24:40.179729+00:00 [queued]>
[2024-05-12T12:41:12.769+0000] {taskinstance.py:1979} INFO - Dependencies all met for dep_context=requeueable deps ti=<TaskInstance: live_ademe.interrogate_api manual__2024-05-12T12:24:40.179729+00:00 [queued]>
[2024-05-12T12:41:12.770+0000] {taskinstance.py:2193} INFO - Starting attempt 4 of 5
[2024-05-12T12:41:12.821+0000] {taskinstance.py:2217} INFO - Executing <Task(PythonOperator): interrogate_api> on 2024-05-12 12:24:40.179729+00:00
[2024-05-12T12:41:12.838+0000] {standard_task_runner.py:60} INFO - Started process 53322 to run task
[2024-05-12T12:41:12.864+0000] {standard_task_runner.py:87} INFO - Running: ['***', 'tasks', 'run', 'live_ademe', 'interrogate_api', 'manual__2024-05-12T12:24:40.179729+00:00', '--job-id', '48', '--raw', '--subdir', 'DAGS_FOLDER/load.py', '--cfg-path', '/tmp/tmplaufn1xg']
[2024-05-12T12:41:12.866+0000] {standard_task_runner.py:88} INFO - Job 48: Subtask interrogate_api
[2024-05-12T12:41:13.012+0000] {task_command.py:423} INFO - Running <TaskInstance: live_ademe.interrogate_api manual__2024-05-12T12:24:40.179729+00:00 [running]> on host 86724742ac03
[2024-05-12T12:41:13.296+0000] {taskinstance.py:2513} INFO - Exporting env vars: AIRFLOW_CTX_DAG_EMAIL='***@example.com' AIRFLOW_CTX_DAG_OWNER='***' AIRFLOW_CTX_DAG_ID='live_ademe' AIRFLOW_CTX_TASK_ID='interrogate_api' AIRFLOW_CTX_EXECUTION_DATE='2024-05-12T12:24:40.179729+00:00' AIRFLOW_CTX_TRY_NUMBER='4' AIRFLOW_CTX_DAG_RUN_ID='manual__2024-05-12T12:24:40.179729+00:00'
[2024-05-12T12:41:13.298+0000] {taskinstance.py:2731} ERROR - Task failed with exception
Traceback (most recent call last):
  File "/home/airflow/.local/lib/python3.8/site-packages/airflow/models/taskinstance.py", line 444, in _execute_task
    result = _execute_callable(context=context, **execute_callable_kwargs)
  File "/home/airflow/.local/lib/python3.8/site-packages/airflow/models/taskinstance.py", line 414, in _execute_callable
    return execute_callable(context=context, **execute_callable_kwargs)
  File "/home/airflow/.local/lib/python3.8/site-packages/airflow/operators/python.py", line 200, in execute
    return_value = self.execute_callable()
  File "/home/airflow/.local/lib/python3.8/site-packages/airflow/operators/python.py", line 217, in execute_callable
    return self.python_callable(*self.op_args, **self.op_kwargs)
  File "/opt/airflow/dags/load.py", line 44, in interrogate_api
    with open(URL_FILE, encoding="utf-8") as file:
FileNotFoundError: [Errno 2] No such file or directory: '../data/api/url.json'
[2024-05-12T12:41:13.342+0000] {taskinstance.py:1149} INFO - Marking task as UP_FOR_RETRY. dag_id=live_ademe, task_id=interrogate_api, execution_date=20240512T122440, start_date=20240512T124112, end_date=20240512T124113
[2024-05-12T12:41:13.399+0000] {standard_task_runner.py:107} ERROR - Failed to execute job 48 for task interrogate_api ([Errno 2] No such file or directory: '../data/api/url.json'; 53322)
[2024-05-12T12:41:13.461+0000] {local_task_job_runner.py:234} INFO - Task exited with return code 1
[2024-05-12T12:41:13.501+0000] {taskinstance.py:3312} INFO - 0 downstream tasks scheduled from follow-on schedule check
