[2024-05-12T12:10:01.198+0000] {taskinstance.py:1979} INFO - Dependencies all met for dep_context=non-requeueable deps ti=<TaskInstance: ademe_data.ademe_api scheduled__2024-05-12T12:05:00+00:00 [queued]>
[2024-05-12T12:10:01.210+0000] {taskinstance.py:1979} INFO - Dependencies all met for dep_context=requeueable deps ti=<TaskInstance: ademe_data.ademe_api scheduled__2024-05-12T12:05:00+00:00 [queued]>
[2024-05-12T12:10:01.210+0000] {taskinstance.py:2193} INFO - Starting attempt 1 of 2
[2024-05-12T12:10:01.230+0000] {taskinstance.py:2217} INFO - Executing <Task(PythonOperator): ademe_api> on 2024-05-12 12:05:00+00:00
[2024-05-12T12:10:01.240+0000] {standard_task_runner.py:60} INFO - Started process 52824 to run task
[2024-05-12T12:10:01.247+0000] {standard_task_runner.py:87} INFO - Running: ['***', 'tasks', 'run', 'ademe_data', 'ademe_api', 'scheduled__2024-05-12T12:05:00+00:00', '--job-id', '27', '--raw', '--subdir', 'DAGS_FOLDER/load_data.py', '--cfg-path', '/tmp/tmpframmzf7']
[2024-05-12T12:10:01.252+0000] {standard_task_runner.py:88} INFO - Job 27: Subtask ademe_api
[2024-05-12T12:10:01.326+0000] {task_command.py:423} INFO - Running <TaskInstance: ademe_data.ademe_api scheduled__2024-05-12T12:05:00+00:00 [running]> on host 86724742ac03
[2024-05-12T12:10:01.434+0000] {taskinstance.py:2513} INFO - Exporting env vars: AIRFLOW_CTX_DAG_EMAIL='yassinemed.essamadi@gmail.com' AIRFLOW_CTX_DAG_OWNER='***' AIRFLOW_CTX_DAG_ID='ademe_data' AIRFLOW_CTX_TASK_ID='ademe_api' AIRFLOW_CTX_EXECUTION_DATE='2024-05-12T12:05:00+00:00' AIRFLOW_CTX_TRY_NUMBER='1' AIRFLOW_CTX_DAG_RUN_ID='scheduled__2024-05-12T12:05:00+00:00'
[2024-05-12T12:10:01.437+0000] {taskinstance.py:2731} ERROR - Task failed with exception
Traceback (most recent call last):
  File "/home/airflow/.local/lib/python3.8/site-packages/airflow/models/taskinstance.py", line 444, in _execute_task
    result = _execute_callable(context=context, **execute_callable_kwargs)
  File "/home/airflow/.local/lib/python3.8/site-packages/airflow/models/taskinstance.py", line 414, in _execute_callable
    return execute_callable(context=context, **execute_callable_kwargs)
  File "/home/airflow/.local/lib/python3.8/site-packages/airflow/operators/python.py", line 200, in execute
    return_value = self.execute_callable()
  File "/home/airflow/.local/lib/python3.8/site-packages/airflow/operators/python.py", line 217, in execute_callable
    return self.python_callable(*self.op_args, **self.op_kwargs)
  File "/opt/airflow/dags/load_data.py", line 79, in ademe_api
    assert os.path.isfile(URL_FILE)
AssertionError
[2024-05-12T12:10:01.448+0000] {taskinstance.py:1149} INFO - Marking task as UP_FOR_RETRY. dag_id=ademe_data, task_id=ademe_api, execution_date=20240512T120500, start_date=20240512T121001, end_date=20240512T121001
[2024-05-12T12:10:01.463+0000] {standard_task_runner.py:107} ERROR - Failed to execute job 27 for task ademe_api (; 52824)
[2024-05-12T12:10:01.499+0000] {local_task_job_runner.py:234} INFO - Task exited with return code 1
[2024-05-12T12:10:01.525+0000] {taskinstance.py:3312} INFO - 0 downstream tasks scheduled from follow-on schedule check
