[2024-05-12T12:04:49.574+0000] {taskinstance.py:1979} INFO - Dependencies all met for dep_context=non-requeueable deps ti=<TaskInstance: live_ademe.check_environment_setup manual__2024-05-12T12:04:47.057920+00:00 [queued]>
[2024-05-12T12:04:49.590+0000] {taskinstance.py:1979} INFO - Dependencies all met for dep_context=requeueable deps ti=<TaskInstance: live_ademe.check_environment_setup manual__2024-05-12T12:04:47.057920+00:00 [queued]>
[2024-05-12T12:04:49.590+0000] {taskinstance.py:2193} INFO - Starting attempt 1 of 2
[2024-05-12T12:04:49.625+0000] {taskinstance.py:2217} INFO - Executing <Task(PythonOperator): check_environment_setup> on 2024-05-12 12:04:47.057920+00:00
[2024-05-12T12:04:49.639+0000] {standard_task_runner.py:60} INFO - Started process 52733 to run task
[2024-05-12T12:04:49.667+0000] {standard_task_runner.py:87} INFO - Running: ['***', 'tasks', 'run', 'live_ademe', 'check_environment_setup', 'manual__2024-05-12T12:04:47.057920+00:00', '--job-id', '19', '--raw', '--subdir', 'DAGS_FOLDER/load.py', '--cfg-path', '/tmp/tmpu0lz5vwd']
[2024-05-12T12:04:49.671+0000] {standard_task_runner.py:88} INFO - Job 19: Subtask check_environment_setup
[2024-05-12T12:04:49.894+0000] {task_command.py:423} INFO - Running <TaskInstance: live_ademe.check_environment_setup manual__2024-05-12T12:04:47.057920+00:00 [running]> on host 86724742ac03
[2024-05-12T12:04:50.178+0000] {taskinstance.py:2513} INFO - Exporting env vars: AIRFLOW_CTX_DAG_EMAIL='***@example.com' AIRFLOW_CTX_DAG_OWNER='***' AIRFLOW_CTX_DAG_ID='live_ademe' AIRFLOW_CTX_TASK_ID='check_environment_setup' AIRFLOW_CTX_EXECUTION_DATE='2024-05-12T12:04:47.057920+00:00' AIRFLOW_CTX_TRY_NUMBER='1' AIRFLOW_CTX_DAG_RUN_ID='manual__2024-05-12T12:04:47.057920+00:00'
[2024-05-12T12:04:50.180+0000] {load.py:21} INFO - ----------------------------------------
[2024-05-12T12:04:50.181+0000] {load.py:23} INFO - [info logger] cwd: /opt/***
[2024-05-12T12:04:50.182+0000] {taskinstance.py:2731} ERROR - Task failed with exception
Traceback (most recent call last):
  File "/home/airflow/.local/lib/python3.8/site-packages/airflow/models/taskinstance.py", line 444, in _execute_task
    result = _execute_callable(context=context, **execute_callable_kwargs)
  File "/home/airflow/.local/lib/python3.8/site-packages/airflow/models/taskinstance.py", line 414, in _execute_callable
    return execute_callable(context=context, **execute_callable_kwargs)
  File "/home/airflow/.local/lib/python3.8/site-packages/airflow/operators/python.py", line 200, in execute
    return_value = self.execute_callable()
  File "/home/airflow/.local/lib/python3.8/site-packages/airflow/operators/python.py", line 217, in execute_callable
    return self.python_callable(*self.op_args, **self.op_kwargs)
  File "/opt/airflow/dags/load.py", line 24, in check_environment_setup
    assert os.path.isfile(URL_FILE)
AssertionError
[2024-05-12T12:04:50.212+0000] {taskinstance.py:1149} INFO - Marking task as UP_FOR_RETRY. dag_id=live_ademe, task_id=check_environment_setup, execution_date=20240512T120447, start_date=20240512T120449, end_date=20240512T120450
[2024-05-12T12:04:50.239+0000] {standard_task_runner.py:107} ERROR - Failed to execute job 19 for task check_environment_setup (; 52733)
[2024-05-12T12:04:50.265+0000] {local_task_job_runner.py:234} INFO - Task exited with return code 1
[2024-05-12T12:04:50.301+0000] {taskinstance.py:3312} INFO - 0 downstream tasks scheduled from follow-on schedule check
